<?xml version="1.0"?>
<robot xmlns:xacro="http://www.ros.org/wiki/xacro">
    <!-- Import macro files -->
    <xacro:include filename="$(find uuv_descriptions)/urdf/common.urdf.xacro" />
    <xacro:include filename="$(find uuv_sensor_ros_plugins)/urdf/sensor_snippets.xacro"/>
    <xacro:include filename="$(find uuv_gazebo_ros_plugins)/urdf/snippets.xacro"/>
    <!--xacro:include filename="$(find mur_description)/urdf/mur_snippets.xacro"/-->
    <!-- Properties -->
    <xacro:property name="mass" value="11.4"/> <!--The real value is 11.4, but it was changed for the simulation. The real life add 1kg to the robot.-->
    <xacro:property name="volume" value="0.012349"/> <!--0.012349-->
    <xacro:property name="cob" value="0 0.005 0.075"/>
    <xacro:property name="rho" value="1000.0"/>

    <xacro:property name="visual_mesh_file" value="file://$(find mur_description)/meshes/mur_5.dae"/>
    <xacro:property name="collision_mesh_file" value="file://$(find mur_description)/meshes/mur_5.dae"/>

    <xacro:macro name="mur_base_5" params="namespace debug">
        <!-- Base link definition -->
        <link name="${namespace}/base_link">
            <visual>
                <origin xyz="0 0 0" rpy="0 0 0"/>
                <geometry>
                    <mesh filename="${visual_mesh_file}" scale="1 1 1" />
                </geometry>
            </visual>

            <collision>
                <origin xyz="0 0 0" rpy="0 0 0"/>
                    <geometry>
                        <mesh filename="${collision_mesh_file}" scale="1 1 1" />
                    </geometry>
            </collision>
            <inertial>
              <mass value="${mass}" />
              <origin xyz="0 0 0" rpy="0 0 0"/>
              <inertia ixx="0.2222" ixy="0" ixz="0"
                       iyy="0.1496" iyz="0"
                       izz="0.320" />
            </inertial>
        </link>

        <joint name="base_joint" type="revolute">
            <axis xyz="1 0 0"/>
            <origin xyz="0 -0.079 -0.1045" rpy="0.92 0 0"/>
            <parent link="${namespace}/base_link"/>
            <child link="${namespace}/arm/link"/>
            <calibration rising="0.0"/>
            <dynamics damping="1.0" friction="2.0"/>
            <limit effort="10" velocity="0.025" lower="-6.28" upper="6.28" />
        </joint>

        <!-- Link definition -->
        <link name="${namespace}/arm/link">
            <visual>
                <origin xyz="0 0 0" rpy="0 0 0"/>
                <geometry>
                  <mesh filename="file://$(find mur_description)/meshes/link.dae" scale="1 1 1" />
                </geometry>
            </visual>
            <collision>
                <origin xyz="0 0 0" rpy="0 0 0"/>
                <geometry>
                  <mesh filename="file://$(find mur_description)/meshes/link.dae" scale="1 1 1" />
                </geometry>
            </collision>
            <inertial>
              <mass value="0.191" />
              <origin xyz="0 0 0" rpy="0 0 0"/>
              <inertia ixx="0.000540" ixy="0" ixz="0.000026"
                       iyy="0.000554" iyz="0"
                       izz="0.000035" />
            </inertial>
        </link>

        <joint name="gripper_joint" type="fixed">
            <origin xyz="0.0175 0 -0.18" rpy="0 0 0"/>
            <parent link="${namespace}/arm/link"/>
            <child link="${namespace}/arm/gripper"/>
        </joint>

        <!-- Gripper definition -->
        <link name="${namespace}/arm/gripper">
            <visual>
                <origin xyz="0 0 0.005" rpy="0 3.141592 0"/>
                <geometry>
                  <mesh filename="file://$(find mur_description)/meshes/gripper.dae" scale="1 1 1" />
                </geometry>
            </visual>
            <collision>
                <origin xyz="0 0 0.005" rpy="0 3.141592 0"/>
                <geometry>
                  <mesh filename="file://$(find mur_description)/meshes/gripper.dae" scale="1 1 1" />
                </geometry>
            </collision>
            <inertial>
              <mass value="0.185" />
              <origin xyz="0 0 0" rpy="0 0 0"/>
              <inertia ixx="0.000299" ixy="0" ixz="0"
                       iyy="0.000299" iyz="0"
                       izz="0.000123" />
            </inertial>
        </link>

  <!-- Set up hydrodynamic plugin-->
      <gazebo>
        <plugin name="${namespace}_uuv_plugin" filename="libuuv_underwater_object_ros_plugin.so">
          <fluid_density>${rho}</fluid_density>
          <flow_velocity_topic>hydrodynamics/current_velocity</flow_velocity_topic>
          <debug>${debug}</debug>
          <link name="${namespace}/base_link">
            <volume>${volume}</volume>
            <center_of_buoyancy>${cob}</center_of_buoyancy>
            <neutrally_buoyant>0</neutrally_buoyant>
            <hydrodynamic_model>
              <type>fossen</type>
              <added_mass>
                ${mass*0.2404}  0       0       0       0       0
                0       ${mass*0.9024}  0       0       0       0
                0       0       ${mass*0.8283}  0       0       0
                0       0       0       0.2222  0       0
                0       0       0       0       0.1492  0
                0       0       0       0       0       0.3209
              </added_mass>
              <!--<linear_damping_forward_speed>
                -8      0       0       0       0       0
                0       -162    0       0       0       150
                0       0       -108    0       -100    0
                0       0       0       -13     0       0
                0       0       37      0       -20     0
                0       -34     0       0       0       -32
              </linear_damping_forward_speed>-->
              <linear_damping>
                -0.6508 -1.0745 -0.3834 -5.1103 -3.7588 -14.3219
              </linear_damping>

              <quadratic_damping>
                -17.4666 -50.8618 -55.7484 -743.0698 -546.5597 -677.9363
              </quadratic_damping>
            </hydrodynamic_model>
          </link>
        </plugin>
        <plugin name="${namespace}_arm" filename="libgazebo_ros_control.so">
          <robotNamespace>${namespace}</robotNamespace>
        </plugin>
      </gazebo>

      <!-- Transmission -->
      <transmission name="base_to_link_trans">
        <type>transmission_interface/SimpleTransmission</type>
        <actuator name="motor1">
          <mechanicalReduction>1</mechanicalReduction>
        </actuator>
        <joint name="base_joint">
          <hardwareInterface>EffortJointInterface</hardwareInterface>
        </joint>
      </transmission>

      <xacro:include filename="$(find mur_description)/urdf/mur_sensors.xacro"/>
      <xacro:include filename="$(find mur_description)/urdf/mur_actuators_5.xacro"/>
    </xacro:macro>
</robot>
